<mujoco model="panda">
    <compiler angle="radian" meshdir="meshes/" />
<!--    <option tolerance="1e-06" collision="predefined" cone="elliptic" jacobian="sparse" solver="CG" iterations="30" />-->
    <size njmax="500" nconmax="100" />
    <asset>
        <mesh name="link0" file="visual/link0_.stl" />
        <mesh name="link1" file="visual/link1_.stl" />
        <mesh name="link2" file="visual/link2_.stl" />
        <mesh name="link3" file="visual/link3_.stl" />
        <mesh name="link4" file="visual/link4_.stl" />
        <mesh name="link5" file="visual/link5_.stl" />
        <mesh name="link6" file="visual/link6_.stl" />
        <mesh name="link7" file="collision/link7.stl" />
        <mesh name="finger" file="visual/finger_.stl" />
        <mesh name="hand" file="visual/hand_.stl" />
        <mesh name="link0_c" file="collision/link0.stl" />
        <mesh name="link1_c" file="collision/link1.stl" />
        <mesh name="link2_c" file="collision/link2.stl" />
        <mesh name="link3_c" file="collision/link3.stl" />
        <mesh name="link4_c" file="collision/link4.stl" />
        <mesh name="link5_c" file="collision/link5.stl" />
        <mesh name="link6_c" file="collision/link6.stl" />
        <mesh name="link7_c" file="collision/link7.stl" />
        <mesh name="finger_c" file="collision/finger.stl" />
        <mesh name="hand_c" file="collision/hand.stl" />
    </asset>
    <worldbody>
        <!-- 로봇의 위치 결정 ! 아래 pos  -->
        <body name="panda_link0" pos="1 0 0">
            <geom type="mesh" rgba="1 1 1 1" mesh="link0"/>
<!--            <geom mesh="link0_c" class="collision"/>-->
            <body name="panda_link1" pos="0 0 0.333">
                <inertial pos="0 -0.04 -0.05" mass="2.7" diaginertia="0.1 0.1 0.1" />
                <joint name="panda_joint1" pos="0 0 0" axis="0 0 1" limited="true" range="-2.9671 2.9671" />
                <geom type="mesh" rgba="1 1 1 1" mesh="link1" />
    <!--            <geom mesh="link1_c" class="collision"/>-->
                <body name="panda_link2" pos="0 0 0" quat="0.707107 -0.707107 0 0">
                    <inertial pos="0 -0.04 0.06" mass="2.73" diaginertia="0.1 0.1 0.1" />
                    <joint name="panda_joint2" pos="0 0 0" axis="0 0 1" limited="true" range="-1.8326 1.8326" />
                    <geom type="mesh" rgba="1 1 1 1" mesh="link2" />
    <!--                <geom mesh="link2_c" class="collision"/>-->
                    <body name="panda_link3" pos="0 -0.316 0" quat="0.707107 0.707107 0 0">
                        <inertial pos="0.01 0.01 -0.05" mass="2.04" diaginertia="0.1 0.1 0.1" />
                        <joint name="panda_joint3" pos="0 0 0" axis="0 0 1" limited="true" range="-2.9671 2.9671" />
                        <geom type="mesh" rgba="1 1 1 1" mesh="link3" />
    <!--                    <geom mesh="link3_c" class="collision"/>-->
                        <body name="panda_link4" pos="0.0825 0 0" quat="0.707107 0.707107 0 0">
                            <inertial pos="-0.03 0.03 0.02" mass="2.08" diaginertia="0.1 0.1 0.1" />
                            <joint name="panda_joint4" pos="0 0 0" axis="0 0 1" limited="true" range="-3.1416 0" />
                            <geom type="mesh" rgba="1 1 1 1" mesh="link4" />
    <!--                        <geom mesh="link4_c" class="collision"/>-->
                            <body name="panda_link5" pos="-0.0825 0.384 0" quat="0.707107 -0.707107 0 0">
                                <inertial pos="0 0.04 -0.12" mass="3" diaginertia="0.1 0.1 0.1" />
                                <joint name="panda_joint5" pos="0 0 0" axis="0 0 1" limited="true" range="-2.9671 2.9671" />
                                <geom type="mesh" rgba="1 1 1 1" mesh="link5" />
    <!--                            <geom mesh="link5_c" class="collision"/>-->
                                <body name="panda_link6" pos="0 0 0" quat="0.707107 0.707107 0 0">
                                    <inertial pos="0.04 0 0" mass="1.3" diaginertia="0.1 0.1 0.1" />
                                    <joint name="panda_joint6" pos="0 0 0" axis="0 0 1" limited="true" range="-0.0873 3.8223" />
                                    <geom type="mesh" rgba="1 1 1 1" mesh="link6" />
    <!--                                <geom mesh="link6_c" class="collision"/>-->
                                    <body name="panda_link7" pos="0.088 0 0" quat="0.707107 0.707107 0 0">
                                        <inertial pos="0 0 0.08" mass="0.2" diaginertia="0.1 0.1 0.1" />
                                        <joint name="panda_joint7" pos="0 0 0" axis="0 0 1" limited="true" range="-2.9671 2.9671" />
                                        <geom type="mesh" rgba="1 1 1 1" mesh="link7" />
    <!--                                    <geom mesh="link7_c" class="collision"/>-->


                                        <body name="hand" pos="0 0 0.107" quat="0.9238795 0 0 -0.3826834">
                                            <inertial mass="0.73" pos="-0.01 0 0.03" diaginertia="0.001 0.0025 0.0017"/>
                                            <geom type="mesh" rgba="1 1 1 1" mesh="hand" />
    <!--                                        <geom mesh="hand_c" class="collision"/>-->
                                            <body name="left_finger" pos="0 0 0.0584">
                                                <inertial mass="0.015" pos="0 0 0" diaginertia="2.375e-6 2.375e-6 7.5e-7"/>
    <!--                                            <joint name="panda_joint6" pos="0 0 0" axis="0 0 1" limited="true" range="-0.0873 3.8223" />-->
                                                <joint type="slide" name="finger_joint1" pos="0 0 0" axis="0 1 0" limited="true" range="0 0.04"/>
                                                <geom type="mesh" rgba="1 1 1 1" mesh="finger" />
    <!--                                            <geom mesh="finger_c" class="collision"/>-->
                                            </body>
                                            <body name="right_finger" pos="0 0 0.0584" quat="0 0 0 1">
                                                <inertial mass="0.015" pos="0 0 0" diaginertia="2.375e-6 2.375e-6 7.5e-7"/>
                                                <joint type="slide" name="finger_joint2" pos="0 0 0" axis="0 1 0" limited="true" range="0 0.04"/>
                                                <geom type="mesh" rgba="1 1 1 1" mesh="finger" />
    <!--                                            <geom mesh="finger_c" class="collision"/>-->

                                            </body>

                                        </body>
                                    </body>
                                </body>
                            </body>
                        </body>
                    </body>
                </body>
            </body>
        </body>
    </worldbody>
    <actuator>
        <!-- <position name="j1" ctrlrange="-2.9671 2.9671" joint="panda_joint2" kp = "300"/>
        <position name="j2" ctrlrange="-1.8326 1.8326" joint="panda_joint3" kp = "300"/>
        <position name="j3" ctrlrange="-2.9671 2.9671" joint="panda_joint4" kp = "300"/>
        <position name="j4" ctrlrange="-3.1416 0" joint="panda_joint2" kp = "300"/>
        <position name="j5" ctrlrange="-2.9671 2.9671" joint="panda_joint5" kp = "300"/>
        <position name="j6" ctrlrange="-0.0873 3.8223" joint="panda_joint6" kp = "300"/>
        <position name="j7" ctrlrange="-2.9671 2.9671" joint="panda_joint7" kp = "300"/> -->

        <!-- Physical limits of the actuator. -->
        <motor ctrllimited="true" ctrlrange="-80.0 80.0" joint="panda_joint1" name="torque_j1"/>
        <motor ctrllimited="true" ctrlrange="-80.0 80.0" joint="panda_joint2" name="torque_j2"/>
        <motor ctrllimited="true" ctrlrange="-80.0 80.0" joint="panda_joint3" name="torque_j3"/>
        <motor ctrllimited="true" ctrlrange="-80.0 80.0" joint="panda_joint4" name="torque_j4"/>
        <motor ctrllimited="true" ctrlrange="-80.0 80.0" joint="panda_joint5" name="torque_j5"/>
        <motor ctrllimited="true" ctrlrange="-12.0 12.0" joint="panda_joint6" name="torque_j6"/>
        <motor ctrllimited="true" ctrlrange="-12.0 12.0" joint="panda_joint7" name="torque_j7"/>
        <position ctrllimited="true" ctrlrange="-1 1" joint="finger_joint1" name="actuator8"/>
        <position ctrllimited="true" ctrlrange="-1 1" joint="finger_joint2" name="actuator9"/>
    </actuator>
</mujoco>
